2024-11-26 19:58:23.968 | ERROR    | aria2p.api:parse_input_file:851 - Skipping download because of invalid option line '  max-download-limit100000'
2024-11-26 19:58:23.968 | TRACE    | aria2p.api:parse_input_file:852 - not enough values to unpack (expected 2, got 1)
Traceback (most recent call last):

  File "<string>", line 1, in <module>
    import sys;exec(eval(sys.stdin.readline()))
  File "<string>", line 8, in <module>
  File "/media/data/dev/aria2p/.venvs/3.13/lib/python3.13/site-packages/execnet/gateway_base.py", line 1806, in serve
    WorkerGateway(io=io, id=id, _startcount=2).serve()
  File "/media/data/dev/aria2p/.venvs/3.13/lib/python3.13/site-packages/execnet/gateway_base.py", line 1273, in serve
    self._execpool.integrate_as_primary_thread()
  File "/media/data/dev/aria2p/.venvs/3.13/lib/python3.13/site-packages/execnet/gateway_base.py", line 389, in integrate_as_primary_thread
    self._perform_spawn(reply)
  File "/media/data/dev/aria2p/.venvs/3.13/lib/python3.13/site-packages/execnet/gateway_base.py", line 411, in _perform_spawn
    reply.run()
  File "/media/data/dev/aria2p/.venvs/3.13/lib/python3.13/site-packages/execnet/gateway_base.py", line 341, in run
    self._result = func(*args, **kwargs)
  File "/media/data/dev/aria2p/.venvs/3.13/lib/python3.13/site-packages/execnet/gateway_base.py", line 1291, in executetask
    exec(co, loc)
  File "/media/data/dev/aria2p/.venvs/3.13/lib/python3.13/site-packages/xdist/remote.py", line 393, in <module>
    config.hook.pytest_cmdline_main(config=config)
  File "/media/data/dev/aria2p/.venvs/3.13/lib/python3.13/site-packages/pluggy/_hooks.py", line 513, in __call__
    return self._hookexec(self.name, self._hookimpls.copy(), kwargs, firstresult)
  File "/media/data/dev/aria2p/.venvs/3.13/lib/python3.13/site-packages/pluggy/_manager.py", line 120, in _hookexec
    return self._inner_hookexec(hook_name, methods, kwargs, firstresult)
  File "/media/data/dev/aria2p/.venvs/3.13/lib/python3.13/site-packages/pluggy/_callers.py", line 103, in _multicall
    res = hook_impl.function(*args)
  File "/media/data/dev/aria2p/.venvs/3.13/lib/python3.13/site-packages/_pytest/main.py", line 330, in pytest_cmdline_main
    return wrap_session(config, _main)
  File "/media/data/dev/aria2p/.venvs/3.13/lib/python3.13/site-packages/_pytest/main.py", line 283, in wrap_session
    session.exitstatus = doit(config, session) or 0
  File "/media/data/dev/aria2p/.venvs/3.13/lib/python3.13/site-packages/_pytest/main.py", line 337, in _main
    config.hook.pytest_runtestloop(session=session)
  File "/media/data/dev/aria2p/.venvs/3.13/lib/python3.13/site-packages/pluggy/_hooks.py", line 513, in __call__
    return self._hookexec(self.name, self._hookimpls.copy(), kwargs, firstresult)
  File "/media/data/dev/aria2p/.venvs/3.13/lib/python3.13/site-packages/pluggy/_manager.py", line 120, in _hookexec
    return self._inner_hookexec(hook_name, methods, kwargs, firstresult)
  File "/media/data/dev/aria2p/.venvs/3.13/lib/python3.13/site-packages/pluggy/_callers.py", line 103, in _multicall
    res = hook_impl.function(*args)
  File "/media/data/dev/aria2p/.venvs/3.13/lib/python3.13/site-packages/xdist/remote.py", line 174, in pytest_runtestloop
    self.run_one_test()
  File "/media/data/dev/aria2p/.venvs/3.13/lib/python3.13/site-packages/xdist/remote.py", line 195, in run_one_test
    self.config.hook.pytest_runtest_protocol(item=item, nextitem=nextitem)
  File "/media/data/dev/aria2p/.venvs/3.13/lib/python3.13/site-packages/pluggy/_hooks.py", line 513, in __call__
    return self._hookexec(self.name, self._hookimpls.copy(), kwargs, firstresult)
  File "/media/data/dev/aria2p/.venvs/3.13/lib/python3.13/site-packages/pluggy/_manager.py", line 120, in _hookexec
    return self._inner_hookexec(hook_name, methods, kwargs, firstresult)
  File "/media/data/dev/aria2p/.venvs/3.13/lib/python3.13/site-packages/pluggy/_callers.py", line 103, in _multicall
    res = hook_impl.function(*args)
  File "/media/data/dev/aria2p/.venvs/3.13/lib/python3.13/site-packages/pytest_rerunfailures.py", line 566, in pytest_runtest_protocol
    reports = runtestprotocol(item, nextitem=nextitem, log=False)
  File "/media/data/dev/aria2p/.venvs/3.13/lib/python3.13/site-packages/_pytest/runner.py", line 132, in runtestprotocol
    reports.append(call_and_report(item, "call", log))
  File "/media/data/dev/aria2p/.venvs/3.13/lib/python3.13/site-packages/_pytest/runner.py", line 241, in call_and_report
    call = CallInfo.from_call(
  File "/media/data/dev/aria2p/.venvs/3.13/lib/python3.13/site-packages/_pytest/runner.py", line 341, in from_call
    result: TResult | None = func()
  File "/media/data/dev/aria2p/.venvs/3.13/lib/python3.13/site-packages/_pytest/runner.py", line 242, in <lambda>
    lambda: runtest_hook(item=item, **kwds), when=when, reraise=reraise
  File "/media/data/dev/aria2p/.venvs/3.13/lib/python3.13/site-packages/pluggy/_hooks.py", line 513, in __call__
    return self._hookexec(self.name, self._hookimpls.copy(), kwargs, firstresult)
  File "/media/data/dev/aria2p/.venvs/3.13/lib/python3.13/site-packages/pluggy/_manager.py", line 120, in _hookexec
    return self._inner_hookexec(hook_name, methods, kwargs, firstresult)
  File "/media/data/dev/aria2p/.venvs/3.13/lib/python3.13/site-packages/pluggy/_callers.py", line 103, in _multicall
    res = hook_impl.function(*args)
  File "/media/data/dev/aria2p/.venvs/3.13/lib/python3.13/site-packages/_pytest/runner.py", line 174, in pytest_runtest_call
    item.runtest()
  File "/media/data/dev/aria2p/.venvs/3.13/lib/python3.13/site-packages/_pytest/python.py", line 1627, in runtest
    self.ihook.pytest_pyfunc_call(pyfuncitem=self)
  File "/media/data/dev/aria2p/.venvs/3.13/lib/python3.13/site-packages/pluggy/_hooks.py", line 513, in __call__
    return self._hookexec(self.name, self._hookimpls.copy(), kwargs, firstresult)
  File "/media/data/dev/aria2p/.venvs/3.13/lib/python3.13/site-packages/pluggy/_manager.py", line 120, in _hookexec
    return self._inner_hookexec(hook_name, methods, kwargs, firstresult)
  File "/media/data/dev/aria2p/.venvs/3.13/lib/python3.13/site-packages/pluggy/_callers.py", line 103, in _multicall
    res = hook_impl.function(*args)
  File "/media/data/dev/aria2p/.venvs/3.13/lib/python3.13/site-packages/_pytest/python.py", line 159, in pytest_pyfunc_call
    result = testfunction(**testargs)

  File "/media/data/dev/aria2p/tests/test_api.py", line 368, in test_parse_input_file
    downloads = api.parse_input_file(INPUT_FILES[1])

> File "/media/data/dev/aria2p/src/aria2p/api.py", line 847, in parse_input_file
    option_name, option_value = option_line.split("=", 1)

ValueError: not enough values to unpack (expected 2, got 1)
2024-11-26 19:58:23.974 | ERROR    | aria2p.api:parse_input_file:851 - Skipping download because of invalid option line '  max-download-limit 100000'
2024-11-26 19:58:23.974 | TRACE    | aria2p.api:parse_input_file:852 - not enough values to unpack (expected 2, got 1)
Traceback (most recent call last):

  File "<string>", line 1, in <module>
    import sys;exec(eval(sys.stdin.readline()))
  File "<string>", line 8, in <module>
  File "/media/data/dev/aria2p/.venvs/3.13/lib/python3.13/site-packages/execnet/gateway_base.py", line 1806, in serve
    WorkerGateway(io=io, id=id, _startcount=2).serve()
  File "/media/data/dev/aria2p/.venvs/3.13/lib/python3.13/site-packages/execnet/gateway_base.py", line 1273, in serve
    self._execpool.integrate_as_primary_thread()
  File "/media/data/dev/aria2p/.venvs/3.13/lib/python3.13/site-packages/execnet/gateway_base.py", line 389, in integrate_as_primary_thread
    self._perform_spawn(reply)
  File "/media/data/dev/aria2p/.venvs/3.13/lib/python3.13/site-packages/execnet/gateway_base.py", line 411, in _perform_spawn
    reply.run()
  File "/media/data/dev/aria2p/.venvs/3.13/lib/python3.13/site-packages/execnet/gateway_base.py", line 341, in run
    self._result = func(*args, **kwargs)
  File "/media/data/dev/aria2p/.venvs/3.13/lib/python3.13/site-packages/execnet/gateway_base.py", line 1291, in executetask
    exec(co, loc)
  File "/media/data/dev/aria2p/.venvs/3.13/lib/python3.13/site-packages/xdist/remote.py", line 393, in <module>
    config.hook.pytest_cmdline_main(config=config)
  File "/media/data/dev/aria2p/.venvs/3.13/lib/python3.13/site-packages/pluggy/_hooks.py", line 513, in __call__
    return self._hookexec(self.name, self._hookimpls.copy(), kwargs, firstresult)
  File "/media/data/dev/aria2p/.venvs/3.13/lib/python3.13/site-packages/pluggy/_manager.py", line 120, in _hookexec
    return self._inner_hookexec(hook_name, methods, kwargs, firstresult)
  File "/media/data/dev/aria2p/.venvs/3.13/lib/python3.13/site-packages/pluggy/_callers.py", line 103, in _multicall
    res = hook_impl.function(*args)
  File "/media/data/dev/aria2p/.venvs/3.13/lib/python3.13/site-packages/_pytest/main.py", line 330, in pytest_cmdline_main
    return wrap_session(config, _main)
  File "/media/data/dev/aria2p/.venvs/3.13/lib/python3.13/site-packages/_pytest/main.py", line 283, in wrap_session
    session.exitstatus = doit(config, session) or 0
  File "/media/data/dev/aria2p/.venvs/3.13/lib/python3.13/site-packages/_pytest/main.py", line 337, in _main
    config.hook.pytest_runtestloop(session=session)
  File "/media/data/dev/aria2p/.venvs/3.13/lib/python3.13/site-packages/pluggy/_hooks.py", line 513, in __call__
    return self._hookexec(self.name, self._hookimpls.copy(), kwargs, firstresult)
  File "/media/data/dev/aria2p/.venvs/3.13/lib/python3.13/site-packages/pluggy/_manager.py", line 120, in _hookexec
    return self._inner_hookexec(hook_name, methods, kwargs, firstresult)
  File "/media/data/dev/aria2p/.venvs/3.13/lib/python3.13/site-packages/pluggy/_callers.py", line 103, in _multicall
    res = hook_impl.function(*args)
  File "/media/data/dev/aria2p/.venvs/3.13/lib/python3.13/site-packages/xdist/remote.py", line 174, in pytest_runtestloop
    self.run_one_test()
  File "/media/data/dev/aria2p/.venvs/3.13/lib/python3.13/site-packages/xdist/remote.py", line 195, in run_one_test
    self.config.hook.pytest_runtest_protocol(item=item, nextitem=nextitem)
  File "/media/data/dev/aria2p/.venvs/3.13/lib/python3.13/site-packages/pluggy/_hooks.py", line 513, in __call__
    return self._hookexec(self.name, self._hookimpls.copy(), kwargs, firstresult)
  File "/media/data/dev/aria2p/.venvs/3.13/lib/python3.13/site-packages/pluggy/_manager.py", line 120, in _hookexec
    return self._inner_hookexec(hook_name, methods, kwargs, firstresult)
  File "/media/data/dev/aria2p/.venvs/3.13/lib/python3.13/site-packages/pluggy/_callers.py", line 103, in _multicall
    res = hook_impl.function(*args)
  File "/media/data/dev/aria2p/.venvs/3.13/lib/python3.13/site-packages/pytest_rerunfailures.py", line 566, in pytest_runtest_protocol
    reports = runtestprotocol(item, nextitem=nextitem, log=False)
  File "/media/data/dev/aria2p/.venvs/3.13/lib/python3.13/site-packages/_pytest/runner.py", line 132, in runtestprotocol
    reports.append(call_and_report(item, "call", log))
  File "/media/data/dev/aria2p/.venvs/3.13/lib/python3.13/site-packages/_pytest/runner.py", line 241, in call_and_report
    call = CallInfo.from_call(
  File "/media/data/dev/aria2p/.venvs/3.13/lib/python3.13/site-packages/_pytest/runner.py", line 341, in from_call
    result: TResult | None = func()
  File "/media/data/dev/aria2p/.venvs/3.13/lib/python3.13/site-packages/_pytest/runner.py", line 242, in <lambda>
    lambda: runtest_hook(item=item, **kwds), when=when, reraise=reraise
  File "/media/data/dev/aria2p/.venvs/3.13/lib/python3.13/site-packages/pluggy/_hooks.py", line 513, in __call__
    return self._hookexec(self.name, self._hookimpls.copy(), kwargs, firstresult)
  File "/media/data/dev/aria2p/.venvs/3.13/lib/python3.13/site-packages/pluggy/_manager.py", line 120, in _hookexec
    return self._inner_hookexec(hook_name, methods, kwargs, firstresult)
  File "/media/data/dev/aria2p/.venvs/3.13/lib/python3.13/site-packages/pluggy/_callers.py", line 103, in _multicall
    res = hook_impl.function(*args)
  File "/media/data/dev/aria2p/.venvs/3.13/lib/python3.13/site-packages/_pytest/runner.py", line 174, in pytest_runtest_call
    item.runtest()
  File "/media/data/dev/aria2p/.venvs/3.13/lib/python3.13/site-packages/_pytest/python.py", line 1627, in runtest
    self.ihook.pytest_pyfunc_call(pyfuncitem=self)
  File "/media/data/dev/aria2p/.venvs/3.13/lib/python3.13/site-packages/pluggy/_hooks.py", line 513, in __call__
    return self._hookexec(self.name, self._hookimpls.copy(), kwargs, firstresult)
  File "/media/data/dev/aria2p/.venvs/3.13/lib/python3.13/site-packages/pluggy/_manager.py", line 120, in _hookexec
    return self._inner_hookexec(hook_name, methods, kwargs, firstresult)
  File "/media/data/dev/aria2p/.venvs/3.13/lib/python3.13/site-packages/pluggy/_callers.py", line 103, in _multicall
    res = hook_impl.function(*args)
  File "/media/data/dev/aria2p/.venvs/3.13/lib/python3.13/site-packages/_pytest/python.py", line 159, in pytest_pyfunc_call
    result = testfunction(**testargs)

  File "/media/data/dev/aria2p/tests/test_api.py", line 371, in test_parse_input_file
    downloads = api.parse_input_file(INPUT_FILES[2])

> File "/media/data/dev/aria2p/src/aria2p/api.py", line 847, in parse_input_file
    option_name, option_value = option_line.split("=", 1)

ValueError: not enough values to unpack (expected 2, got 1)
2024-11-26 19:58:23.979 | ERROR    | aria2p.api:parse_input_file:851 - Skipping download because of invalid option line '  max-resume-failure-tries10'
2024-11-26 19:58:23.980 | TRACE    | aria2p.api:parse_input_file:852 - not enough values to unpack (expected 2, got 1)
Traceback (most recent call last):

  File "<string>", line 1, in <module>
    import sys;exec(eval(sys.stdin.readline()))
  File "<string>", line 8, in <module>
  File "/media/data/dev/aria2p/.venvs/3.13/lib/python3.13/site-packages/execnet/gateway_base.py", line 1806, in serve
    WorkerGateway(io=io, id=id, _startcount=2).serve()
  File "/media/data/dev/aria2p/.venvs/3.13/lib/python3.13/site-packages/execnet/gateway_base.py", line 1273, in serve
    self._execpool.integrate_as_primary_thread()
  File "/media/data/dev/aria2p/.venvs/3.13/lib/python3.13/site-packages/execnet/gateway_base.py", line 389, in integrate_as_primary_thread
    self._perform_spawn(reply)
  File "/media/data/dev/aria2p/.venvs/3.13/lib/python3.13/site-packages/execnet/gateway_base.py", line 411, in _perform_spawn
    reply.run()
  File "/media/data/dev/aria2p/.venvs/3.13/lib/python3.13/site-packages/execnet/gateway_base.py", line 341, in run
    self._result = func(*args, **kwargs)
  File "/media/data/dev/aria2p/.venvs/3.13/lib/python3.13/site-packages/execnet/gateway_base.py", line 1291, in executetask
    exec(co, loc)
  File "/media/data/dev/aria2p/.venvs/3.13/lib/python3.13/site-packages/xdist/remote.py", line 393, in <module>
    config.hook.pytest_cmdline_main(config=config)
  File "/media/data/dev/aria2p/.venvs/3.13/lib/python3.13/site-packages/pluggy/_hooks.py", line 513, in __call__
    return self._hookexec(self.name, self._hookimpls.copy(), kwargs, firstresult)
  File "/media/data/dev/aria2p/.venvs/3.13/lib/python3.13/site-packages/pluggy/_manager.py", line 120, in _hookexec
    return self._inner_hookexec(hook_name, methods, kwargs, firstresult)
  File "/media/data/dev/aria2p/.venvs/3.13/lib/python3.13/site-packages/pluggy/_callers.py", line 103, in _multicall
    res = hook_impl.function(*args)
  File "/media/data/dev/aria2p/.venvs/3.13/lib/python3.13/site-packages/_pytest/main.py", line 330, in pytest_cmdline_main
    return wrap_session(config, _main)
  File "/media/data/dev/aria2p/.venvs/3.13/lib/python3.13/site-packages/_pytest/main.py", line 283, in wrap_session
    session.exitstatus = doit(config, session) or 0
  File "/media/data/dev/aria2p/.venvs/3.13/lib/python3.13/site-packages/_pytest/main.py", line 337, in _main
    config.hook.pytest_runtestloop(session=session)
  File "/media/data/dev/aria2p/.venvs/3.13/lib/python3.13/site-packages/pluggy/_hooks.py", line 513, in __call__
    return self._hookexec(self.name, self._hookimpls.copy(), kwargs, firstresult)
  File "/media/data/dev/aria2p/.venvs/3.13/lib/python3.13/site-packages/pluggy/_manager.py", line 120, in _hookexec
    return self._inner_hookexec(hook_name, methods, kwargs, firstresult)
  File "/media/data/dev/aria2p/.venvs/3.13/lib/python3.13/site-packages/pluggy/_callers.py", line 103, in _multicall
    res = hook_impl.function(*args)
  File "/media/data/dev/aria2p/.venvs/3.13/lib/python3.13/site-packages/xdist/remote.py", line 174, in pytest_runtestloop
    self.run_one_test()
  File "/media/data/dev/aria2p/.venvs/3.13/lib/python3.13/site-packages/xdist/remote.py", line 195, in run_one_test
    self.config.hook.pytest_runtest_protocol(item=item, nextitem=nextitem)
  File "/media/data/dev/aria2p/.venvs/3.13/lib/python3.13/site-packages/pluggy/_hooks.py", line 513, in __call__
    return self._hookexec(self.name, self._hookimpls.copy(), kwargs, firstresult)
  File "/media/data/dev/aria2p/.venvs/3.13/lib/python3.13/site-packages/pluggy/_manager.py", line 120, in _hookexec
    return self._inner_hookexec(hook_name, methods, kwargs, firstresult)
  File "/media/data/dev/aria2p/.venvs/3.13/lib/python3.13/site-packages/pluggy/_callers.py", line 103, in _multicall
    res = hook_impl.function(*args)
  File "/media/data/dev/aria2p/.venvs/3.13/lib/python3.13/site-packages/pytest_rerunfailures.py", line 566, in pytest_runtest_protocol
    reports = runtestprotocol(item, nextitem=nextitem, log=False)
  File "/media/data/dev/aria2p/.venvs/3.13/lib/python3.13/site-packages/_pytest/runner.py", line 132, in runtestprotocol
    reports.append(call_and_report(item, "call", log))
  File "/media/data/dev/aria2p/.venvs/3.13/lib/python3.13/site-packages/_pytest/runner.py", line 241, in call_and_report
    call = CallInfo.from_call(
  File "/media/data/dev/aria2p/.venvs/3.13/lib/python3.13/site-packages/_pytest/runner.py", line 341, in from_call
    result: TResult | None = func()
  File "/media/data/dev/aria2p/.venvs/3.13/lib/python3.13/site-packages/_pytest/runner.py", line 242, in <lambda>
    lambda: runtest_hook(item=item, **kwds), when=when, reraise=reraise
  File "/media/data/dev/aria2p/.venvs/3.13/lib/python3.13/site-packages/pluggy/_hooks.py", line 513, in __call__
    return self._hookexec(self.name, self._hookimpls.copy(), kwargs, firstresult)
  File "/media/data/dev/aria2p/.venvs/3.13/lib/python3.13/site-packages/pluggy/_manager.py", line 120, in _hookexec
    return self._inner_hookexec(hook_name, methods, kwargs, firstresult)
  File "/media/data/dev/aria2p/.venvs/3.13/lib/python3.13/site-packages/pluggy/_callers.py", line 103, in _multicall
    res = hook_impl.function(*args)
  File "/media/data/dev/aria2p/.venvs/3.13/lib/python3.13/site-packages/_pytest/runner.py", line 174, in pytest_runtest_call
    item.runtest()
  File "/media/data/dev/aria2p/.venvs/3.13/lib/python3.13/site-packages/_pytest/python.py", line 1627, in runtest
    self.ihook.pytest_pyfunc_call(pyfuncitem=self)
  File "/media/data/dev/aria2p/.venvs/3.13/lib/python3.13/site-packages/pluggy/_hooks.py", line 513, in __call__
    return self._hookexec(self.name, self._hookimpls.copy(), kwargs, firstresult)
  File "/media/data/dev/aria2p/.venvs/3.13/lib/python3.13/site-packages/pluggy/_manager.py", line 120, in _hookexec
    return self._inner_hookexec(hook_name, methods, kwargs, firstresult)
  File "/media/data/dev/aria2p/.venvs/3.13/lib/python3.13/site-packages/pluggy/_callers.py", line 103, in _multicall
    res = hook_impl.function(*args)
  File "/media/data/dev/aria2p/.venvs/3.13/lib/python3.13/site-packages/_pytest/python.py", line 159, in pytest_pyfunc_call
    result = testfunction(**testargs)

  File "/media/data/dev/aria2p/tests/test_api.py", line 371, in test_parse_input_file
    downloads = api.parse_input_file(INPUT_FILES[2])

> File "/media/data/dev/aria2p/src/aria2p/api.py", line 847, in parse_input_file
    option_name, option_value = option_line.split("=", 1)

ValueError: not enough values to unpack (expected 2, got 1)
